Workbook

Sheet README
A1: IdleFarm Balance Bible | B1: Design authority for tunable progression and economy.
A2: Target | B2: Focused free player reaches Node Exploration Lv.100 in 28–32 days.
A3: Level model | B3: Each Production Node owns an independent Exploration Level.
A4: Lv.1–100 | B4: Vanilla pools only.
A5: Lv.101+ | B5: Adds MMORPG materials while retaining vanilla output.
A6: Yellow cells | B6: Primary tuning assumptions.
A7: Formula cells | B7: Derived outputs; do not replace without updating the model.
A8: Credits | B8: 1 Credit purchase price = 1 THB; non-cashable and non-transferable.
A9: Important | B9: Weights do not replace daily/weekly rare-item caps.

Sheet Assumptions
A1: Core assumptions
A2: Key | B2: Value | C2: Unit | D2: Design note
A3: xp_base | B3: 120 | C3: EXP | D3: EXP_next = base + step × current level
A4: xp_step | B4: 12 | C4: EXP/level | D4: Stable curve
A5: passive_typical | B5: 650 | C5: EXP/day | D5: Focused node with normal check-ins
A6: passive_cap | B6: 900 | C6: EXP/day | D6: Per node
A7: first_collect | B7: 100 | C7: EXP/day | D7: Focused node
A8: focused_commission | B8: 400 | C8: EXP/day | D8: Focused node
A9: first_expedition | B9: 700 | C9: EXP/day | D9: Focused node
A10: extra_expedition_cap | B10: 300 | C10: EXP/day | D10: 100 per additional completion
A11: weekly_chapter | B11: 3500 | C11: EXP/week | D11: Focused node
A12: tutorial | B12: 2000 | C12: EXP | D12: One time
A13: buffer_per_tier | B13: 256 | C13: items | D13: Target 2–3 check-ins/day
A14: full_research_factor | B14: 0.25 | C14: ratio | D14: Research while buffer full
... A16: hybrid_pay_cap | B16: 0.15 | C16: ratio | D16: Per qualifying checkout

Sheet XP Curve
A1: Exploration Level curve
A2: Current level | B2: EXP to next | C2: Cumulative EXP | D2: Milestone
A3: 1 | B3: 132 | C3: 0
A4: 2 | B4: 144 | C4: 132
A5: 3 | B5: 156 | C5: 276
A6: 4 | B6: 168 | C6: 432
A7: 5 | B7: 180 | C7: 600
A8: 6 | B8: 192 | C8: 780
A9: 7 | B9: 204 | C9: 972
A10: 8 | B10: 216 | C10: 1176
A11: 9 | B11: 228 | C11: 1392
A12: 10 | B12: 240 | C12: 1620 | D12: Bracket II
A13: 11 | B13: 252 | C13: 1860
A14: 12 | B14: 264 | C14: 2112
A15: 13 | B15: 276 | C15: 2376
A16: 14 | B16: 288 | C16: 2652
A17: 15 | B17: 300 | C17: 2940
A18: 16 | B18: 312 | C18: 3240
A19: 17 | B19: 324 | C19: 3552
A20: 18 | B20: 336 | C20: 3876
A21: 19 | B21: 348 | C21: 4212
A22: 20 | B22: 360 | C22: 4560
A23: 21 | B23: 372 | C23: 4920
A24: 22 | B24: 384 | C24: 5292
... A26: 24 | B26: 408 | C26: 6072
A27: 25 | B27: 420 | C27: 6480 | D27: Specialization I
A28: 26 | B28: 432 | C28: 6900
A29: 27 | B29: 444 | C29: 7332
A30: 28 | B30: 456 | C30: 7776
A31: 29 | B31: 468 | C31: 8232
A32: 30 | B32: 480 | C32: 8700
A33: 31 | B33: 492 | C33: 9180
A34: 32 | B34: 504 | C34: 9672
A35: 33 | B35: 516 | C35: 10176
A36: 34 | B36: 528 | C36: 10692
A37: 35 | B37: 540 | C37: 11220
A38: 36 | B38: 552 | C38: 11760
A39: 37 | B39: 564 | C39: 12312
... A51: 49 | B51: 708 | C51: 19872
A52: 50 | B52: 720 | C52: 20580 | D52: Specialization II
...

Sheet 30 Day Simulation
A1: Focused-node 30-day simulation
A2: Day | B2: Passive | C2: Collect | D2: Commission | E2: First expedition | F2: Extra expedition | G2: Weekly | H2: Tutorial | I2: Daily total | J2: Cumulative | K2: Projected level
A3: 1 | B3: 650 | C3: 100 | D3: 400 | E3: 700 | F3: 0 | G3: 0 | H3: 2000 | I3: =SUM(B3:H3) | J3: =IF(A3=1,I3,J2+I3) | K3: =LOOKUP(J3,'XP Curve'!$C$3:$C$102,'XP Curve'!$A$3:$A$102)
A4: 2 | B4: 650 | C4: 100 | D4: 400 | E4: 700 | F4: 0 | G4: 0 | H4: 0 | I4: =SUM(B4:H4) | J4: =IF(A4=1,I4,J3+I4) | K4: =LOOKUP(J4,'XP Curve'!$C$3:$C$102,'XP Curve'!$A$3:$A$102)
A5: 3 | B5: 650 | C5: 100 | D5: 400 | E5: 700 | F5: 0 | G5: 0 | H5: 0 | I5: =SUM(B5:H5) | J5: =IF(A5=1,I5,J4+I5) | K5: =LOOKUP(J5,'XP Curve'!$C$3:$C$102,'XP Curve'!$A$3:$A$102)
A6: 4 | B6: 650 | C6: 100 | D6: 400 | E6: 700 | F6: 0 | G6: 0 | H6: 0 | I6: =SUM(B6:H6) | J6: =IF(A6=1,I6,J5+I6) | K6: =LOOKUP(J6,'XP Curve'!$C$3:$C$102,'XP Curve'!$A$3:$A$102)
A7: 5 | B7: 650 | C7: 100 | D7: 400 | E7: 700 | F7: 0 | G7: 0 | H7: 0 | I7: =SUM(B7:H7) | J7: =IF(A7=1,I7,J6+I7) | K7: =LOOKUP(J7,'XP Curve'!$C$3:$C$102,'XP Curve'!$A$3:$A$102)
A8: 6 | B8: 650 | C8: 100 | D8: 400 | E8: 700 | F8: 0 | G8: 0 | H8: 0 | I8: =SUM(B8:H8) | J8: =IF(A8=1,I8,J7+I8) | K8: =LOOKUP(J8,'XP Curve'!$C$3:$C$102,'XP Curve'!$A$3:$A$102)
A9: 7 | B9: 650 | C9: 100 | D9: 400 | E9: 700 | F9: 0 | G9: 3500 | H9: 0 | I9: =SUM(B9:H9) | J9: =IF(A9=1,I9,J8+I9) | K9: =LOOKUP(J9,'XP Curve'!$C$3:$C$102,'XP Curve'!$A$3:$A$102)
A10: 8 | B10: 650 | C10: 100 | D10: 400 | E10: 700 | F10: 0 | G10: 0 | H10: 0 | I10: =SUM(B10:H10) | J10: =IF(A10=1,I10,J9+I10) | K10: =LOOKUP(J10,'XP Curve'!$C$3:$C$102,'XP Curve'!$A$3:$A$102)
A11: 9 | B11: 650 | C11: 100 | D11: 400 | E11: 700 | F11: 0 | G11: 0 | H11: 0 | I11: =SUM(B11:H11) | J11: =IF(A11=1,I11,J10+I11) | K11: =LOOKUP(J11,'XP Curve'!$C$3:$C$102,'XP Curve'!$A$3:$A$102)
A12: 10 | B12: 650 | C12: 100 | D12: 400 | E12: 700 | F12: 0 | G12: 0 | H12: 0 | I12: =SUM(B12:H12) | J12: =IF(A12=1,I12,J11+I12) | K12: =LOOKUP(J12,'XP Curve'!$C$3:$C$102,'XP Curve'!$A$3:$A$102)
A13: 11 | B13: 650 | C13: 100 | D13: 400 | E13: 700 | F13: 0 | G13: 0 | H13: 0 | I13: =SUM(B13:H13) | J13: =IF(A13=1,I13,J12+I13) | K13: =LOOKUP(J13,'XP Curve'!$C$3:$C$102,'XP Curve'!$A$3:$A$102)
A14: 12 | B14: 650 | C14: 100 | D14: 400 | E14: 700 | F14: 0 | G14: 0 | H14: 0 | I14: =SUM(B14:H14) | J14: =IF(A14=1,I14,J13+I14) | K14: =LOOKUP(J14,'XP Curve'!$C$3:$C$102,'XP Curve'!$A$3:$A$102)
... A32: 30 | B32: 650 | C32: 100 | D32: 400 | E32: 700 | F32: 0 | G32: 0 | H32: 0 | I32: =SUM(B32:H32) | J32: =IF(A32=1,I32,J31+I32) | K32: =LOOKUP(J32,'XP Curve'!$C$3:$C$102,'XP Curve'!$A$3:$A$102)

Sheet Production
A1: Production and buffer model
A2: Node | B2: Tier | C2: Workers | D2: Base/hour | E2: Rarity power | F2: Worker level | G2: Avg diligence | H2: Estimated/hour | I2: Buffer | J2: Hours to full
A3: Mining | B3: 1 | C3: 1 | D3: 40 | E3: 1 | F3: 10 | G3: 10 | H3: =D3*C3*E3*(1+F3*0.02)*(1+G3/100) | I3: =256*B3 | J3: =I3/H3
A4: Mining | B4: 2 | C4: 2 | D4: 40 | E4: 1 | F4: 10 | G4: 10 | H4: =D4*C4*E4*(1+F4*0.02)*(1+G4/100) | I4: =256*B4 | J4: =I4/H4
A5: Mining | B5: 3 | C5: 3 | D5: 40 | E5: 1 | F5: 10 | G5: 10 | H5: =D5*C5*E5*(1+F5*0.02)*(1+G5/100) | I5: =256*B5 | J5: =I5/H5
A6: Mining | B6: 4 | C6: 4 | D6: 40 | E6: 1 | F6: 10 | G6: 10 | H6: =D6*C6*E6*(1+F6*0.02)*(1+G6/100) | I6: =256*B6 | J6: =I6/H6
A7: Mining | B7: 5 | C7: 5 | D7: 40 | E7: 1 | F7: 10 | G7: 10 | H7: =D7*C7*E7*(1+F7*0.02)*(1+G7/100) | I7: =256*B7 | J7: =I7/H7
A8: Farming | B8: 1 | C8: 1 | D8: 48 | E8: 1 | F8: 10 | G8: 10 | H8: =D8*C8*E8*(1+F8*0.02)*(1+G8/100) | I8: =256*B8 | J8: =I8/H8
A9: Farming | B9: 2 | C9: 2 | D9: 48 | E9: 1 | F9: 10 | G9: 10 | H9: =D9*C9*E9*(1+F9*0.02)*(1+G9/100) | I9: =256*B9 | J9: =I9/H9
A10: Farming | B10: 3 | C10: 3 | D10: 48 | E10: 1 | F10: 10 | G10: 10 | H10: =D10*C10*E10*(1+F10*0.02)*(1+G10/100) | I10: =256*B10 | J10: =I10/H10
A11: Farming | B11: 4 | C11: 4 | D11: 48 | E11: 1 | F11: 10 | G11: 10 | H11: =D11*C11*E11*(1+F11*0.02)*(1+G11/100) | I11: =256*B11 | J11: =I11/H11
A12: Farming | B12: 5 | C12: 5 | D12: 48 | E12: 1 | F12: 10 | G12: 10 | H12: =D12*C12*E12*(1+F12*0.02)*(1+G12/100) | I12: =256*B12 | J12: =I12/H12
A13: Woodcutting | B13: 1 | C13: 1 | D13: 44 | E13: 1 | F13: 10 | G13: 10 | H13: =D13*C13*E13*(1+F13*0.02)*(1+G13/100) | I13: =256*B13 | J13: =I13/H13
A14: Woodcutting | B14: 2 | C14: 2 | D14: 44 | E14: 1 | F14: 10 | G14: 10 | H14: =D14*C14*E14*(1+F14*0.02)*(1+G14/100) | I14: =256*B14 | J14: =I14/H14
... A27: Hunter | B27: 5 | C27: 5 | D27: 30 | E27: 1 | F27: 10 | G27: 10 | H27: =D27*C27*E27*(1+F27*0.02)*(1+G27/100) | I27: =256*B27 | J27: =I27/H27

Sheet Coin Economy
A1: Month-one Coin economy
A2: Category | B2: Source/Sink | C2: Monthly Coins | D2: Assumption
A3: Income | B3: Online payout | C3: 36000 | D3: 60 hours × 600/hour
A4: Income | B4: Daily behavior commissions | C4: 18000 | D4: 600/day
A5: Income | B5: Weekly chapters | C5: 8000 | D5: 2,000/week
A6: Income | B6: Achievements | C6: 10000 | D6: Journey/Mastery budget
A7: Income | B7: Expected Global Expedition | C7: 2000 | D7: Participation expectation
A8: Sink | B8: Production claims | C8: -4000 | D8: Four after free starter
A9: Sink | B9: Primary T1→T5 | C9: -11872 | D9: Exact current formula
A10: Sink | B10: Three secondary T2 | C10: -3000 | D10: 1,000 each
A11: Sink | B11: 20 hires | C11: -5000 | D11: 250 each
A12: Sink | B12: Fuse catalysts/respec | C12: -6000 | D12: Expected
A13: Sink | B13: Warehouse expansion | C13: -5000 | D13: One purchase
A14: Sink | B14: Bag/utility/cosmetics | C14: -8000 | D14: Player choice
A15: Net | B15: Month-one remainder | C15: =SUM(C3:C14) | D15: Choice budget

Sheet Credits
A1: Hybrid Pay rules
A2: Rule | B2: Value | C2: Purpose
A3: Purchase price | B3: 1 Credit = 1 THB | C3: External checkout price, not redemption value
A4: Coin offset | B4: 20 Coins/Credit | C4: Checkout only
A5: Per-purchase cap | B5: 15% | C5: At least 85% earned Coins
A6: Season cap | B6: 30,000 Coin offset | C6: Also ≤25% of Coins earned
A7: Never allowed | B7: EXP, RNG, tradable items, MMORPG materials | C7: Fairness
A8: Transfer/cashout | B8: Never | C8: Server entitlement only

Sheet Mining Drops
A1: Mining Drops
A2: Material | B2: Unlock bracket | C2: B1 weight | D2: B2 weight | E2: B3 weight | F2: B4 weight | G2: B5 weight | H2: B6 weight | I2: B7 weight | J2: B8 weight | K2: B9 weight | L2: B10 weight | M2: Daily cap | N2: Weekly cap | O2: Source
A3: COBBLESTONE | B3: 1 | C3: 60 | D3: 45 | E3: 35 | F3: 28 | G3: 22 | H3: 18 | I3: 15 | J3: 12 | K3: 10 | L3: 8 | O3: Passive
A4: STONE | B4: 1 | C4: 25 | D4: 20 | E4: 17 | F4: 14 | G4: 12 | H4: 10 | I4: 8 | J4: 7 | K4: 6 | L4: 5 | O4: Passive
A5: COAL | B5: 1 | C5: 15 | D5: 20 | E5: 20 | F5: 18 | G5: 16 | H5: 14 | I5: 12 | J5: 10 | K5: 9 | L5: 8 | O5: Passive
A6: DEEPSLATE | B6: 2 | C6: 0 | D6: 10 | E6: 10 | F6: 9 | G6: 8 | H6: 7 | I6: 6 | J6: 5 | K6: 4 | L6: 4 | O6: Passive
A7: RAW_COPPER | B7: 2 | C7: 0 | D7: 5 | E7: 8 | F7: 8 | G7: 7 | H7: 6 | I7: 5 | J7: 5 | K7: 4 | L7: 4 | O7: Passive
A8: RAW_IRON | B8: 3 | C8: 0 | D8: 0 | E8: 8 | F8: 12 | G8: 15 | H8: 17 | I8: 18 | J8: 18 | K8: 18 | L8: 18 | O8: Passive
A9: FLINT | B9: 3 | C9: 0 | D9: 0 | E9: 2 | F9: 2 | G9: 2 | H9: 2 | I9: 2 | J9: 2 | K9: 2 | L9: 2 | O9: Passive
A10: REDSTONE | B10: 4 | C10: 0 | D10: 0 | E10: 0 | F10: 5 | G10: 8 | H10: 10 | I10: 12 | J10: 13 | K10: 14 | L10: 14 | O10: Passive
A11: RAW_GOLD | B11: 4 | C11: 0 | D11: 0 | E11: 0 | F11: 3 | G11: 5 | H11: 7 | I11: 8 | J11: 9 | K11: 10 | L11: 10 | O11: Passive
A12: LAPIS_LAZULI | B12: 5 | C12: 0 | D12: 0 | E12: 0 | F12: 0 | G12: 5 | H12: 7 | I12: 8 | J12: 9 | K12: 10 | L12: 10 | O12: Passive
A13: QUARTZ | B13: 5 | C13: 0 | D13: 0 | E13: 0 | F13: 0 | G13: 4 | H13: 5 | I13: 6 | J13: 7 | K13: 8 | L13: 8 | O13: Passive
A14: AMETHYST_SHARD | B14: 6 | C14: 0 | D14: 0 | E14: 0 | F14: 0 | G14: 0 | H14: 3 | I14: 4 | J14: 5 | K14: 6 | L14: 7 | O14: Passive
A15: DIAMOND | B15: 6 | C15: 0 | D15: 0 | E15: 0 | F15: 0 | G15: 0 | H15: 1 | I15: 1.5 | J15: 2 | K15: 2.5 | L15: 3 | M15: 8/16 | O15: Passive capped
A16: EMERALD | B16: 7 | C16: 0 | D16: 0 | E16: 0 | F16: 0 | G16: 0 | H16: 0 | I16: 1 | J16: 1.5 | K16: 2 | L16: 2.5 | M16: 12 | O16: Passive capped
A17: OBSIDIAN | B17: 8 | C17: 0 | D17: 0 | E17: 0 | F17: 0 | G17: 0 | H17: 0 | I17: 0 | J17: 1 | K17: 1.5 | L17: 2 | O17: Passive
A18: ANCIENT_DEBRIS | B18: 10 | C18: 0 | D18: 0 | E18: 0 | F18: 0 | G18: 0 | H18: 0 | I18: 0 | J18: 0 | K18: 0 | L18: 0.2 | N18: 2 shared | O18: Passive capped

Sheet Farming Drops
A1: Farming Drops
A2: Material | B2: Unlock bracket | C2: B1 weight | D2: B2 weight | E2: B3 weight | F2: B4 weight | G2: B5 weight | H2: B6 weight | I2: B7 weight | J2: B8 weight | K2: B9 weight | L2: B10 weight | M2: Daily cap | N2: Weekly cap | O2: Source
A3: WHEAT | B3: 1 | C3: 50 | D3: 40 | E3: 32 | F3: 27 | G3: 23 | H3: 20 | I3: 18 | J3: 16 | K3: 14 | L3: 12 | O3: Passive
A4: CARROT | B4: 1 | C4: 30 | D4: 25 | E4: 22 | F4: 19 | G4: 17 | H4: 15 | I4: 14 | J4: 13 | K4: 12 | L4: 11 | O4: Passive
A5: POTATO | B5: 1 | C5: 20 | D5: 20 | E5: 18 | F5: 16 | G5: 14 | H5: 13 | I5: 12 | J5: 11 | K5: 10 | L5: 9 | O5: Passive
A6: BEETROOT | B6: 2 | C6: 0 | D6: 8 | E6: 9 | F6: 9 | G6: 8 | H6: 8 | I6: 7 | J6: 7 | K6: 6 | L6: 6 | O6: Passive
A7: PUMPKIN | B7: 2 | C7: 0 | D7: 4 | E7: 6 | F7: 7 | G7: 7 | H7: 7 | I7: 7 | J7: 7 | K7: 7 | L7: 7 | O7: Passive
A8: MELON_SLICE | B8: 2 | C8: 0 | D8: 3 | E8: 5 | F8: 6 | G8: 6 | H8: 6 | I8: 6 | J8: 6 | K8: 6 | L8: 6 | O8: Passive
A9: SUGAR_CANE | B9: 3 | C9: 0 | D9: 0 | E9: 6 | F9: 8 | G9: 9 | H9: 10 | I9: 10 | J9: 10 | K9: 10 | L9: 10 | O9: Passive
A10: CACTUS | B10: 3 | C10: 0 | D10: 0 | E10: 3 | F10: 4 | G10: 5 | H10: 5 | I10: 5 | J10: 5 | K10: 5 | L10: 5 | O10: Passive
A11: COCOA_BEANS | B11: 3 | C11: 0 | D11: 0 | E11: 3 | F11: 4 | G11: 5 | H11: 5 | I11: 5 | J11: 5 | K11: 5 | L11: 5 | O11: Passive
A12: BROWN_MUSHROOM | B12: 4 | C12: 0 | D12: 0 | E12: 0 | F12: 4 | G12: 5 | H12: 5 | I12: 6 | J12: 6 | K12: 6 | L12: 6 | O12: Passive
A13: SWEET_BERRIES | B13: 4 | C13: 0 | D13: 0 | E13: 0 | F13: 4 | G13: 5 | H13: 6 | I13: 6 | J13: 6 | K13: 6 | L13: 6 | O13: Passive
A14: BAMBOO | B14: 4 | C14: 0 | D14: 0 | E14: 0 | F14: 4 | G14: 5 | H14: 6 | I14: 6 | J14: 6 | K14: 6 | L14: 6 | O14: Passive
... A17: CHORUS_FRUIT | B17: 8 | C17: 0 | D17: 0 | E17: 0 | F17: 0 | G17: 0 | H17: 0 | I17: 0 | J17: 1 | K17: 2 | L17: 3 | O17: Event/Passive

Sheet Wood Drops
A1: Wood Drops
A2: Material | B2: Unlock bracket | C2: B1 weight | D2: B2 weight | E2: B3 weight | F2: B4 weight | G2: B5 weight | H2: B6 weight | I2: B7 weight | J2: B8 weight | K2: B9 weight | L2: B10 weight | M2: Daily cap | N2: Weekly cap | O2: Source
A3: OAK_LOG | B3: 1 | C3: 45 | D3: 35 | E3: 28 | F3: 24 | G3: 21 | H3: 18 | I3: 16 | J3: 14 | K3: 12 | L3: 10 | O3: Passive
A4: BIRCH_LOG | B4: 1 | C4: 30 | D4: 25 | E4: 21 | F4: 18 | G4: 16 | H4: 14 | I4: 13 | J4: 12 | K4: 11 | L4: 10 | O4: Passive
A5: SPRUCE_LOG | B5: 1 | C5: 25 | D5: 23 | E5: 20 | F5: 18 | G5: 16 | H5: 15 | I5: 14 | J5: 13 | K5: 12 | L5: 11 | O5: Passive
A6: JUNGLE_LOG | B6: 2 | C6: 0 | D6: 9 | E6: 11 | F6: 12 | G6: 12 | H6: 12 | I6: 12 | J6: 12 | K6: 12 | L6: 12 | O6: Passive
A7: ACACIA_LOG | B7: 2 | C7: 0 | D7: 8 | E7: 10 | F7: 11 | G7: 11 | H7: 11 | I7: 11 | J7: 11 | K7: 11 | L7: 11 | O7: Passive
A8: DARK_OAK_LOG | B8: 3 | C8: 0 | D8: 0 | E8: 10 | F8: 12 | G8: 13 | H8: 14 | I8: 14 | J8: 14 | K8: 14 | L8: 14 | O8: Passive
A9: MANGROVE_LOG | B9: 3 | C9: 0 | D9: 0 | E9: 6 | F9: 8 | G9: 9 | H9: 10 | I9: 10 | J9: 10 | K9: 10 | L9: 10 | O9: Passive
A10: CHERRY_LOG | B10: 4 | C10: 0 | D10: 0 | E10: 0 | F10: 8 | G10: 10 | H10: 11 | I10: 12 | J10: 12 | K10: 12 | L10: 12 | O10: Passive
A11: BAMBOO_BLOCK | B11: 4 | C11: 0 | D11: 0 | E11: 0 | F11: 5 | G11: 7 | H11: 8 | I11: 9 | J11: 9 | K11: 9 | L11: 9 | O11: Passive
A12: CRIMSON_STEM | B12: 6 | C12: 0 | D12: 0 | E12: 0 | F12: 0 | G12: 0 | H12: 2 | I12: 3 | J12: 4 | K12: 5 | L12: 6 | O12: Event/Passive
A13: WARPED_STEM | B13: 6 | C13: 0 | D13: 0 | E13: 0 | F13: 0 | G13: 0 | H13: 2 | I13: 3 | J13: 4 | K13: 5 | L13: 6 | O13: Event/Passive

Sheet Livestock Drops
A1: Livestock Drops
A2: Material | B2: Unlock bracket | C2: B1 weight | D2: B2 weight | E2: B3 weight | F2: B4 weight | G2: B5 weight | H2: B6 weight | I2: B7 weight | J2: B8 weight | K2: B9 weight | L2: B10 weight | M2: Daily cap | N2: Weekly cap | O2: Source
A3: BEEF | B3: 1 | C3: 30 | D3: 25 | E3: 21 | F3: 18 | G3: 16 | H3: 14 | I3: 13 | J3: 12 | K3: 11 | L3: 10 | O3: Passive
A4: PORKCHOP | B4: 1 | C4: 25 | D4: 22 | E4: 19 | F4: 17 | G4: 15 | H4: 14 | I4: 13 | J4: 12 | K4: 11 | L4: 10 | O4: Passive
A5: CHICKEN | B5: 1 | C5: 20 | D5: 18 | E5: 16 | F5: 14 | G5: 13 | H5: 12 | I5: 11 | J5: 10 | K5: 9 | L5: 8 | O5: Passive
A6: EGG | B6: 1 | C6: 25 | D6: 20 | E6: 17 | F6: 15 | G6: 13 | H6: 12 | I6: 11 | J6: 10 | K6: 9 | L6: 8 | O6: Passive
A7: LEATHER | B7: 2 | C7: 0 | D7: 9 | E7: 11 | F7: 12 | G7: 13 | H7: 14 | I7: 15 | J7: 15 | K7: 15 | L7: 15 | O7: Passive
A8: WHITE_WOOL | B8: 2 | C8: 0 | D8: 7 | E8: 9 | F8: 10 | G8: 11 | H8: 12 | I8: 13 | J8: 13 | K8: 13 | L8: 13 | O8: Passive
A9: FEATHER | B9: 2 | C9: 0 | D9: 5 | E9: 6 | F9: 7 | G9: 7 | H9: 7 | I9: 7 | J9: 7 | K9: 7 | L9: 7 | O9: Passive
A10: MILK_BUCKET | B10: 3 | C10: 0 | D10: 0 | E10: 2 | F10: 3 | G10: 4 | H10: 5 | I10: 5 | J10: 5 | K10: 5 | L10: 5 | O10: Passive
A11: RABBIT_HIDE | B11: 3 | C11: 0 | D11: 0 | E11: 3 | F11: 4 | G11: 5 | H11: 6 | I11: 6 | J11: 6 | K11: 6 | L11: 6 | O11: Passive
A12: COD | B12: 4 | C12: 0 | D12: 0 | E12: 0 | F12: 7 | G12: 8 | H12: 9 | I12: 9 | J12: 9 | K12: 9 | L12: 9 | O12: Passive
A13: SALMON | B13: 4 | C13: 0 | D13: 0 | E13: 0 | F13: 5 | G13: 6 | H13: 7 | I13: 7 | J13: 7 | K13: 7 | L13: 7 | O13: Passive
A14: GLOW_INK_SAC | B14: 5 | C14: 0 | D14: 0 | E14: 0 | F14: 0 | G14: 2 | H14: 3 | I14: 4 | J14: 5 | K14: 6 | L14: 7 | O14: Passive
A15: RABBIT_FOOT | B15: 6 | C15: 0 | D15: 0 | E15: 0 | F15: 0 | G15: 0 | H15: 1 | I15: 1.5 | J15: 2 | K15: 2.5 | L15: 3 | O15: Passive
A16: NAUTILUS_SHELL | B16: 6 | C16: 0 | D16: 0 | E16: 0 | F16: 0 | G16: 0 | H16: 0.5 | I16: 0.7 | J16: 1 | K16: 1.2 | L16: 1.5 | M16: 4 | O16: Capped

Sheet Hunter Drops
A1: Hunter Drops
A2: Material | B2: Unlock bracket | C2: B1 weight | D2: B2 weight | E2: B3 weight | F2: B4 weight | G2: B5 weight | H2: B6 weight | I2: B7 weight | J2: B8 weight | K2: B9 weight | L2: B10 weight | M2: Daily cap | N2: Weekly cap | O2: Source
A3: ROTTEN_FLESH | B3: 1 | C3: 40 | D3: 32 | E3: 26 | F3: 21 | G3: 18 | H3: 15 | I3: 13 | J3: 11 | K3: 10 | L3: 9 | O3: Passive
A4: BONE | B4: 1 | C4: 35 | D4: 29 | E4: 25 | F4: 22 | G4: 20 | H4: 18 | I4: 17 | J4: 16 | K4: 15 | L4: 14 | O4: Passive
A5: STRING | B5: 1 | C5: 25 | D5: 22 | E5: 19 | F5: 17 | G5: 15 | H5: 14 | I5: 13 | J5: 12 | K5: 11 | L5: 10 | O5: Passive
A6: GUNPOWDER | B6: 2 | C6: 0 | D6: 9 | E6: 12 | F6: 14 | G6: 15 | H6: 16 | I6: 17 | J6: 18 | K6: 18 | L6: 18 | O6: Passive
A7: SPIDER_EYE | B7: 2 | C7: 0 | D7: 6 | E7: 8 | F7: 9 | G7: 10 | H7: 10 | I7: 10 | J7: 10 | K7: 10 | L7: 10 | O7: Passive
A8: ARROW | B8: 2 | C8: 0 | D8: 5 | E8: 6 | F8: 7 | G8: 7 | H8: 7 | I8: 7 | J8: 7 | K8: 7 | L8: 7 | O8: Passive
A9: SLIME_BALL | B9: 3 | C9: 0 | D9: 0 | E9: 5 | F9: 7 | G9: 8 | H9: 9 | I9: 10 | J9: 10 | K9: 10 | L9: 10 | O9: Passive
A10: MAGMA_CREAM | B10: 3 | C10: 0 | D10: 0 | E10: 2 | F10: 3 | G10: 4 | H10: 5 | I10: 6 | J10: 7 | K10: 8 | L10: 8 | O10: Passive
A11: ENDER_PEARL | B11: 4 | C11: 0 | D11: 0 | E11: 0 | F11: 1 | G11: 1.5 | H11: 2 | I11: 2.5 | J11: 3 | K11: 3.5 | L11: 4 | O11: Passive
A12: BLAZE_ROD | B12: 5 | C12: 0 | D12: 0 | E12: 0 | F12: 0 | G12: 0 | H12: 1 | I12: 1.5 | J12: 2 | K12: 2.5 | L12: 3 | O12: Event until B6
A13: GHAST_TEAR | B13: 6 | C13: 0 | D13: 0 | E13: 0 | F13: 0 | G13: 0 | H13: 0.5 | I13: 0.7 | J13: 1 | K13: 1.2 | L13: 1.5 | M13: 4 | O13: Capped
A14: PHANTOM_MEMBRANE | B14: 6 | C14: 0 | D14: 0 | E14: 0 | F14: 0 | G14: 0 | H14: 1 | I14: 1.5 | J14: 2 | K14: 2.5 | L14: 3 | O14: Passive
A15: PRISMARINE_SHARD | B15: 8 | C15: 0 | D15: 0 | E15: 0 | F15: 0 | G15: 0 | H15: 0 | I15: 0 | J15: 1 | K15: 1.5 | L15: 2 | O15: Event/Passive
A16: WITHER_SKELETON_SKULL | B16: 10 | C16: 0 | D16: 0 | E16: 0 | F16: 0 | G16: 0 | H16: 0 | I16: 0 | J16: 0 | K16: 0 | L16: 0 | N16: 1 | O16: Active event only

Sheet Event Families
A1: Exploration event families
A2: Family | B2: Primary stat | C2: Base duration | D2: Node EXP | E2: Main reward | F2: First bracket
A3: Survey | B3: Stamina | C3: 15 | D3: 700 | E3: Node EXP | F3: 2
A4: Resource Run | B4: Diligence | C4: 25 | D4: 250 | E4: Quantity | F4: 2
A5: Rare Discovery | B5: Luck | C5: 30 | D5: 300 | E5: Rare pool | F5: 4
A6: Rescue | B6: Speed | C6: 12 | D6: 350 | E6: Chronicle/social | F6: 4
A7: Endurance | B7: Stamina + team | C7: 45 | D7: 400 | E7: Worker EXP | F7: 6
A8: Deep Expedition | B8: Balanced | C8: 60 | D8: 600 | E8: Capstone/mastery | F8: 8

Sheet Post 100
A1: Post-100 roll shares
A2: Level range | B2: Vanilla share | C2: MMORPG share | D2: Material tier
A3: 101–110 | B3: 0.9 | C3: 0.1 | D3: Frontier I
A4: 111–125 | B4: 0.8 | C4: 0.2 | D4: Frontier I
A5: 126–150 | B5: 0.7 | C5: 0.3 | D5: Frontier I–II
A6: 151–175 | B6: 0.6 | C6: 0.4 | D6: Frontier II
A7: 176–200 | B7: 0.5 | C7: 0.5 | D7: Frontier II–III

Sheet Achievement Budget
A1: Month-one Achievement budget
A2: Reward | B2: Minimum | C2: Maximum | D2: Rule
A3: Exploration EXP | B3: 1500 | C3: 2000 | D3: Journey only, non-repeatable
A4: Coins | B4: 8000 | C4: 10000 | D4: Journey and Mastery
A5: Chronicle Points | B5: 40 | C5: 60 | D5: Permanent account score
A6: Cosmetics | B6: 6 | C6: 10 | D6: Titles, façades, frames
A7: Functional presets | B7: 1 | C7: 2 | D7: Organization convenience

Sheet Node Type Perks
A1: Node-specific perk milestones
A2: Node | B2: Unlock level | C2: Tier | D2: Perk | E2: Primary function
A3: Mining | B3: 15 | C3: Foundation | D3: Stone Mason | E3: Common-block preference/project routing
A4: Mining | B4: 15 | C4: Foundation | D4: Ore Sense | E4: 30-roll basic-ore pity
A5: Mining | B5: 15 | C5: Foundation | D5: Reinforced Shaft | E5: Buffer/full-research
A6: Mining | B6: 35 | C6: Operations | D6: Seismic Map | E6: Daily event choice
A7: Mining | B7: 35 | C7: Operations | D7: Rich Vein | E7: Prepared quantity
A8: Mining | B8: 35 | C8: Operations | D8: Crystal Echo | E8: Capped-roll fallback
A9: Mining | B9: 60 | C9: Direction | D9: Metal Stratum | E9: Metal preference
A10: Mining | B10: 60 | C10: Direction | D10: Redstone Stratum | E10: Technical-resource preference
A11: Mining | B11: 60 | C11: Direction | D11: Gem Stratum | E11: Gem/event preference
A12: Mining | B12: 85 | C12: Legacy | D12: Deep Core | E12: Advanced-roll meter
A13: Mining | B13: 85 | C13: Legacy | D13: Excavation Crew | E13: Reduced event opportunity cost
A14: Mining | B14: 85 | C14: Legacy | D14: Geological Archive | E14: Journal research
... A62: Hunter | B62: 85 | C62: Legacy | D62: Dread Mark | E62: Event completion EXP
